Workbook

Sheet Names
A1: Courses | B1: Professors | C1: Subjects | D1: Days | E1: Hours
A2: =COUNTA(A3:A1000) -> 18 | B2: =COUNTA(B3:B1000) -> 75 | C2: =COUNTA(C3:C1000) -> 226 | D2: =COUNTA(D3:D1000) -> 5 | E2: =COUNTA(E3:E1000) -> 8
A3: 1A | B3: AC1 | C3: C.Ciudadana 1A | D3: Monday | E3: 08:00 - 08:50
A4: 1B | B4: AA2 | C4: C.Ciudadana 1B | D4: Tuesday | E4: 08:50 - 09:45
A5: 1C | B5: AH4 | C5: C.Ciudadana 1C | D5: Wednesday | E5: 10:00 - 10:50
A6: 2A | B6: BL6 | C6: C.Ciudadana 2A | D6: Thursday | E6: 10:50 - 11:40
A7: 2B | B7: BT7 | C7: C.Ciudadana 2B | D7: Friday | E7: 11:50 - 12:45
A8: 2C | B8: BT8 | C8: C.Ciudadana 2C | E8: 13:30 - 14-30
A9: 3A | B9: CM9 | C9: C.Ciudadana 3A | E9: 14:30 - 15:15
A10: 3B | B10: CF10 | C10: C.Ciudadana 3B | E10: 15:30 - 16:20
A11: 3C | B11: CT11 | C11: C.Ciudadana 3C
A12: 4E | B12: CR14 | C12: Matemática 1A
A13: 4S | B13: DS15 | C13: Matemática 1B
A14: 4N | B14: EA16 | C14: Matemática 1C
A15: 5E | B15: GL19 | C15: Matemática 2A
A16: 5S | B16: GD20 | C16: Matemática 2B
A17: 5N | B17: GI21 | C17: Matemática 2C
A18: 6E | B18: GA22 | C18: Matemática 3A
A19: 6S | B19: GA23 | C19: Matemática 3B
A20: 6N | B20: GK24 | C20: Matemática 3C
B21: HN25 | C21: Matemática 4E
B22: ME26 | C22: Matemática 4S
B23: MF28 | C23: Matemática 4N
B24: NL29 | C24: Matemática 5E
B25: OM30 | C25: Matemática 5S
B26: PV32 | C26: Matemática 5N
B27: PV33 | C27: Matemática 6E
B28: PM34 | C28: Matemática 6S
B29: RD35 | C29: Matemática 6N
B30: RM36 | C30: Cs.Naturales 1A
B31: RM37 | C31: Cs.Naturales 1B
B32: RB38 | C32: Cs.Naturales 1C
... B77: ING18 | C77: Computación 4S
C78: Computación 4N
C79: Computación 5E
C80: Computación 5S
C81: Computación 5N
C82: Computación 6E
C83: Computación 6S
C84: Computación 6N
...

Sheet Courses_disponibility
A1: NOTES: | B1: 1: Active hour ( the course have to be at school at that hour)
B2: 0: Inactive hour ( The course dont have to be at school at that hour)
B3: 2: Optional hour ( The course may or may not be at the scool at that hour)
B6: {=VSTACK( TOROW(MAKEARRAY(Names!D2, Names!E2, LAMBDA(r, c, INDEX(Names!D3:D1005, r)))), TOROW(MAKEARRAY(Names!D2, Names!E2, LAMBDA(r, c, INDEX(Names!E3:E1005, c)))) )} -> Monday | C6: Monday | D6: Monday | E6: Monday | F6: Monday | G6: Monday | H6: Monday | I6: Monday | J6: Tuesday | K6: Tuesday | L6: Tuesday | M6: Tuesday | N6: Tuesday | O6: Tuesday | P6: Tuesday | Q6: Tuesday | R6: Wednesday | S6: Wednesday | T6: Wednesday | U6: Wednesday | V6: Wednesday | W6: Wednesday | X6: Wednesday | Y6: Wednesday | Z6: Thursday | AA6: Thursday | AB6: Thursday | AC6: Thursday | AD6: Thursday | AE6: Thursday | AF6: Thursday | AG6: Thursday | AH6: Friday | AI6: Friday | AJ6: Friday | AK6: Friday | AL6: Friday | AM6: Friday | AN6: Friday | AO6: Friday
B7: 08:00 - 08:50 | C7: 08:50 - 09:45 | D7: 10:00 - 10:50 | E7: 10:50 - 11:40 | F7: 11:50 - 12:45 | G7: 13:30 - 14-30 | H7: 14:30 - 15:15 | I7: 15:30 - 16:20 | J7: 08:00 - 08:50 | K7: 08:50 - 09:45 | L7: 10:00 - 10:50 | M7: 10:50 - 11:40 | N7: 11:50 - 12:45 | O7: 13:30 - 14-30 | P7: 14:30 - 15:15 | Q7: 15:30 - 16:20 | R7: 08:00 - 08:50 | S7: 08:50 - 09:45 | T7: 10:00 - 10:50 | U7: 10:50 - 11:40 | V7: 11:50 - 12:45 | W7: 13:30 - 14-30 | X7: 14:30 - 15:15 | Y7: 15:30 - 16:20 | Z7: 08:00 - 08:50 | AA7: 08:50 - 09:45 | AB7: 10:00 - 10:50 | AC7: 10:50 - 11:40 | AD7: 11:50 - 12:45 | AE7: 13:30 - 14-30 | AF7: 14:30 - 15:15 | AG7: 15:30 - 16:20 | AH7: 08:00 - 08:50 | AI7: 08:50 - 09:45 | AJ7: 10:00 - 10:50 | AK7: 10:50 - 11:40 | AL7: 11:50 - 12:45 | AM7: 13:30 - 14-30 | AN7: 14:30 - 15:15 | AO7: 15:30 - 16:20
A8: {=UNIQUE(Names!A3:A1005)} -> 1A | B8: 1 | C8: 1 | D8: 1 | E8: 1 | F8: 1 | G8: 0 | H8: 0 | I8: 0 | J8: 1 | K8: 1 | L8: 1 | M8: 1 | N8: 1 | O8: 2 | P8: 2 | Q8: 2 | R8: 1 | S8: 1 | T8: 1 | U8: 1 | V8: 1 | W8: 0 | X8: 0 | Y8: 0 | Z8: 1 | AA8: 1 | AB8: 1 | AC8: 1 | AD8: 1 | AE8: 2 | AF8: 2 | AG8: 2 | AH8: 1 | AI8: 1 | AJ8: 1 | AK8: 1 | AL8: 1 | AM8: 2 | AN8: 2 | AO8: 2
A9: 1B | B9: 1 | C9: 1 | D9: 1 | E9: 1 | F9: 1 | G9: 0 | H9: 0 | I9: 0 | J9: 1 | K9: 1 | L9: 1 | M9: 1 | N9: 1 | O9: 2 | P9: 2 | Q9: 2 | R9: 1 | S9: 1 | T9: 1 | U9: 1 | V9: 1 | W9: 0 | X9: 0 | Y9: 0 | Z9: 1 | AA9: 1 | AB9: 1 | AC9: 1 | AD9: 1 | AE9: 2 | AF9: 2 | AG9: 2 | AH9: 1 | AI9: 1 | AJ9: 1 | AK9: 1 | AL9: 1 | AM9: 2 | AN9: 2 | AO9: 2
A10: 1C | B10: 1 | C10: 1 | D10: 1 | E10: 1 | F10: 1 | G10: 0 | H10: 0 | I10: 0 | J10: 1 | K10: 1 | L10: 1 | M10: 1 | N10: 1 | O10: 2 | P10: 2 | Q10: 2 | R10: 1 | S10: 1 | T10: 1 | U10: 1 | V10: 1 | W10: 0 | X10: 0 | Y10: 0 | Z10: 1 | AA10: 1 | AB10: 1 | AC10: 1 | AD10: 1 | AE10: 2 | AF10: 2 | AG10: 2 | AH10: 1 | AI10: 1 | AJ10: 1 | AK10: 1 | AL10: 1 | AM10: 2 | AN10: 2 | AO10: 2
A11: 2A | B11: 1 | C11: 1 | D11: 1 | E11: 1 | F11: 1 | G11: 0 | H11: 0 | I11: 0 | J11: 1 | K11: 1 | L11: 1 | M11: 1 | N11: 1 | O11: 2 | P11: 2 | Q11: 2 | R11: 1 | S11: 1 | T11: 1 | U11: 1 | V11: 1 | W11: 0 | X11: 0 | Y11: 0 | Z11: 1 | AA11: 1 | AB11: 1 | AC11: 1 | AD11: 1 | AE11: 2 | AF11: 2 | AG11: 2 | AH11: 1 | AI11: 1 | AJ11: 1 | AK11: 1 | AL11: 1 | AM11: 2 | AN11: 2 | AO11: 2
A12: 2B | B12: 1 | C12: 1 | D12: 1 | E12: 1 | F12: 1 | G12: 0 | H12: 0 | I12: 0 | J12: 1 | K12: 1 | L12: 1 | M12: 1 | N12: 1 | O12: 2 | P12: 2 | Q12: 2 | R12: 1 | S12: 1 | T12: 1 | U12: 1 | V12: 1 | W12: 0 | X12: 0 | Y12: 0 | Z12: 1 | AA12: 1 | AB12: 1 | AC12: 1 | AD12: 1 | AE12: 2 | AF12: 2 | AG12: 2 | AH12: 1 | AI12: 1 | AJ12: 1 | AK12: 1 | AL12: 1 | AM12: 2 | AN12: 2 | AO12: 2
A13: 2C | B13: 1 | C13: 1 | D13: 1 | E13: 1 | F13: 1 | G13: 0 | H13: 0 | I13: 0 | J13: 1 | K13: 1 | L13: 1 | M13: 1 | N13: 1 | O13: 2 | P13: 2 | Q13: 2 | R13: 1 | S13: 1 | T13: 1 | U13: 1 | V13: 1 | W13: 0 | X13: 0 | Y13: 0 | Z13: 1 | AA13: 1 | AB13: 1 | AC13: 1 | AD13: 1 | AE13: 2 | AF13: 2 | AG13: 2 | AH13: 1 | AI13: 1 | AJ13: 1 | AK13: 1 | AL13: 1 | AM13: 2 | AN13: 2 | AO13: 2
A14: 3A | B14: 1 | C14: 1 | D14: 1 | E14: 1 | F14: 1 | G14: 0 | H14: 0 | I14: 0 | J14: 1 | K14: 1 | L14: 1 | M14: 1 | N14: 1 | O14: 2 | P14: 2 | Q14: 2 | R14: 1 | S14: 1 | T14: 1 | U14: 1 | V14: 1 | W14: 0 | X14: 0 | Y14: 0 | Z14: 1 | AA14: 1 | AB14: 1 | AC14: 1 | AD14: 1 | AE14: 2 | AF14: 2 | AG14: 2 | AH14: 1 | AI14: 1 | AJ14: 1 | AK14: 1 | AL14: 1 | AM14: 2 | AN14: 2 | AO14: 2
A15: 3B | B15: 1 | C15: 1 | D15: 1 | E15: 1 | F15: 1 | G15: 0 | H15: 0 | I15: 0 | J15: 1 | K15: 1 | L15: 1 | M15: 1 | N15: 1 | O15: 2 | P15: 2 | Q15: 2 | R15: 1 | S15: 1 | T15: 1 | U15: 1 | V15: 1 | W15: 0 | X15: 0 | Y15: 0 | Z15: 1 | AA15: 1 | AB15: 1 | AC15: 1 | AD15: 1 | AE15: 2 | AF15: 2 | AG15: 2 | AH15: 1 | AI15: 1 | AJ15: 1 | AK15: 1 | AL15: 1 | AM15: 2 | AN15: 2 | AO15: 2
A16: 3C | B16: 1 | C16: 1 | D16: 1 | E16: 1 | F16: 1 | G16: 0 | H16: 0 | I16: 0 | J16: 1 | K16: 1 | L16: 1 | M16: 1 | N16: 1 | O16: 2 | P16: 2 | Q16: 2 | R16: 1 | S16: 1 | T16: 1 | U16: 1 | V16: 1 | W16: 0 | X16: 0 | Y16: 0 | Z16: 1 | AA16: 1 | AB16: 1 | AC16: 1 | AD16: 1 | AE16: 2 | AF16: 2 | AG16: 2 | AH16: 1 | AI16: 1 | AJ16: 1 | AK16: 1 | AL16: 1 | AM16: 2 | AN16: 2 | AO16: 2
A17: 4E | B17: 1 | C17: 1 | D17: 1 | E17: 1 | F17: 1 | G17: 1 | H17: 0 | I17: 0 | J17: 1 | K17: 1 | L17: 1 | M17: 1 | N17: 1 | O17: 2 | P17: 2 | Q17: 2 | R17: 1 | S17: 1 | T17: 1 | U17: 1 | V17: 1 | W17: 1 | X17: 0 | Y17: 0 | Z17: 1 | AA17: 1 | AB17: 1 | AC17: 1 | AD17: 1 | AE17: 2 | AF17: 2 | AG17: 2 | AH17: 1 | AI17: 1 | AJ17: 1 | AK17: 1 | AL17: 1 | AM17: 2 | AN17: 2 | AO17: 2
A18: 4S | B18: 1 | C18: 1 | D18: 1 | E18: 1 | F18: 1 | G18: 1 | H18: 0 | I18: 0 | J18: 1 | K18: 1 | L18: 1 | M18: 1 | N18: 1 | O18: 2 | P18: 2 | Q18: 2 | R18: 1 | S18: 1 | T18: 1 | U18: 1 | V18: 1 | W18: 1 | X18: 0 | Y18: 0 | Z18: 1 | AA18: 1 | AB18: 1 | AC18: 1 | AD18: 1 | AE18: 2 | AF18: 2 | AG18: 2 | AH18: 1 | AI18: 1 | AJ18: 1 | AK18: 1 | AL18: 1 | AM18: 2 | AN18: 2 | AO18: 2
A19: 4N | B19: 1 | C19: 1 | D19: 1 | E19: 1 | F19: 1 | G19: 1 | H19: 0 | I19: 0 | J19: 1 | K19: 1 | L19: 1 | M19: 1 | N19: 1 | O19: 2 | P19: 2 | Q19: 2 | R19: 1 | S19: 1 | T19: 1 | U19: 1 | V19: 1 | W19: 1 | X19: 0 | Y19: 0 | Z19: 1 | AA19: 1 | AB19: 1 | AC19: 1 | AD19: 1 | AE19: 2 | AF19: 2 | AG19: 2 | AH19: 1 | AI19: 1 | AJ19: 1 | AK19: 1 | AL19: 1 | AM19: 2 | AN19: 2 | AO19: 2
A20: 5E | B20: 1 | C20: 1 | D20: 1 | E20: 1 | F20: 1 | G20: 1 | H20: 0 | I20: 0 | J20: 1 | K20: 1 | L20: 1 | M20: 1 | N20: 1 | O20: 2 | P20: 2 | Q20: 2 | R20: 1 | S20: 1 | T20: 1 | U20: 1 | V20: 1 | W20: 1 | X20: 0 | Y20: 0 | Z20: 1 | AA20: 1 | AB20: 1 | AC20: 1 | AD20: 1 | AE20: 2 | AF20: 2 | AG20: 2 | AH20: 1 | AI20: 1 | AJ20: 1 | AK20: 1 | AL20: 1 | AM20: 2 | AN20: 2 | AO20: 2
... A25: 6N | B25: 1 | C25: 1 | D25: 1 | E25: 1 | F25: 1 | G25: 1 | H25: 0 | I25: 0 | J25: 1 | K25: 1 | L25: 1 | M25: 1 | N25: 1 | O25: 2 | P25: 2 | Q25: 2 | R25: 1 | S25: 1 | T25: 1 | U25: 1 | V25: 1 | W25: 1 | X25: 0 | Y25: 0 | Z25: 1 | AA25: 1 | AB25: 1 | AC25: 1 | AD25: 1 | AE25: 2 | AF25: 2 | AG25: 2 | AH25: 1 | AI25: 1 | AJ25: 1 | AK25: 1 | AL25: 1 | AM25: 2 | AN25: 2 | AO25: 2

Sheet Professors_disponibility
A1: NOTES: | B1: 1: Available ( The professor is available to work that day at that hour)
B2: 0: Unavailable ( The professor is not available to work that day at that hour)
B6: {=VSTACK( TOROW(MAKEARRAY(Names!D2, Names!E2, LAMBDA(r, c, INDEX(Names!D3:D1005, r)))), TOROW(MAKEARRAY(Names!D2, Names!E2, LAMBDA(r, c, INDEX(Names!E3:E1005, c)))) )} -> Monday | C6: Monday | D6: Monday | E6: Monday | F6: Monday | G6: Monday | H6: Monday | I6: Monday | J6: Tuesday | K6: Tuesday | L6: Tuesday | M6: Tuesday | N6: Tuesday | O6: Tuesday | P6: Tuesday | Q6: Tuesday | R6: Wednesday | S6: Wednesday | T6: Wednesday | U6: Wednesday | V6: Wednesday | W6: Wednesday | X6: Wednesday | Y6: Wednesday | Z6: Thursday | AA6: Thursday | AB6: Thursday | AC6: Thursday | AD6: Thursday | AE6: Thursday | AF6: Thursday | AG6: Thursday | AH6: Friday | AI6: Friday | AJ6: Friday | AK6: Friday | AL6: Friday | AM6: Friday | AN6: Friday | AO6: Friday
B7: 08:00 - 08:50 | C7: 08:50 - 09:45 | D7: 10:00 - 10:50 | E7: 10:50 - 11:40 | F7: 11:50 - 12:45 | G7: 13:30 - 14-30 | H7: 14:30 - 15:15 | I7: 15:30 - 16:20 | J7: 08:00 - 08:50 | K7: 08:50 - 09:45 | L7: 10:00 - 10:50 | M7: 10:50 - 11:40 | N7: 11:50 - 12:45 | O7: 13:30 - 14-30 | P7: 14:30 - 15:15 | Q7: 15:30 - 16:20 | R7: 08:00 - 08:50 | S7: 08:50 - 09:45 | T7: 10:00 - 10:50 | U7: 10:50 - 11:40 | V7: 11:50 - 12:45 | W7: 13:30 - 14-30 | X7: 14:30 - 15:15 | Y7: 15:30 - 16:20 | Z7: 08:00 - 08:50 | AA7: 08:50 - 09:45 | AB7: 10:00 - 10:50 | AC7: 10:50 - 11:40 | AD7: 11:50 - 12:45 | AE7: 13:30 - 14-30 | AF7: 14:30 - 15:15 | AG7: 15:30 - 16:20 | AH7: 08:00 - 08:50 | AI7: 08:50 - 09:45 | AJ7: 10:00 - 10:50 | AK7: 10:50 - 11:40 | AL7: 11:50 - 12:45 | AM7: 13:30 - 14-30 | AN7: 14:30 - 15:15 | AO7: 15:30 - 16:20
A8: {=UNIQUE(Names!B3:B1005)} -> AC1 | B8: 1 | C8: 1 | D8: 1 | E8: 1 | F8: 1 | G8: 0 | H8: 0 | I8: 0 | J8: 1 | K8: 1 | L8: 1 | M8: 1 | N8: 1 | O8: 0 | P8: 0 | Q8: 0 | R8: 0 | S8: 0 | T8: 0 | U8: 0 | V8: 0 | W8: 0 | X8: 0 | Y8: 0 | Z8: 0 | AA8: 0 | AB8: 0 | AC8: 0 | AD8: 0 | AE8: 0 | AF8: 0 | AG8: 0 | AH8: 0 | AI8: 0 | AJ8: 0 | AK8: 0 | AL8: 0 | AM8: 0 | AN8: 0 | AO8: 0
A9: AA2 | B9: 1 | C9: 1 | D9: 1 | E9: 1 | F9: 1 | G9: 1 | H9: 1 | I9: 1 | J9: 1 | K9: 1 | L9: 1 | M9: 1 | N9: 1 | O9: 1 | P9: 1 | Q9: 1 | R9: 1 | S9: 1 | T9: 1 | U9: 1 | V9: 1 | W9: 1 | X9: 1 | Y9: 1 | Z9: 1 | AA9: 1 | AB9: 1 | AC9: 1 | AD9: 1 | AE9: 1 | AF9: 1 | AG9: 1 | AH9: 1 | AI9: 1 | AJ9: 1 | AK9: 1 | AL9: 1 | AM9: 1 | AN9: 1 | AO9: 1
A10: AH4 | B10: 0 | C10: 0 | D10: 0 | E10: 0 | F10: 0 | G10: 0 | H10: 0 | I10: 0 | J10: 1 | K10: 1 | L10: 1 | M10: 1 | N10: 0 | O10: 0 | P10: 0 | Q10: 0 | R10: 0 | S10: 0 | T10: 1 | U10: 1 | V10: 0 | W10: 0 | X10: 0 | Y10: 0 | Z10: 1 | AA10: 1 | AB10: 1 | AC10: 1 | AD10: 0 | AE10: 0 | AF10: 0 | AG10: 0 | AH10: 1 | AI10: 1 | AJ10: 1 | AK10: 1 | AL10: 0 | AM10: 0 | AN10: 0 | AO10: 0
A11: BL6 | B11: 1 | C11: 1 | D11: 0 | E11: 0 | F11: 0 | G11: 0 | H11: 0 | I11: 0 | J11: 1 | K11: 1 | L11: 0 | M11: 0 | N11: 0 | O11: 0 | P11: 0 | Q11: 0 | R11: 1 | S11: 1 | T11: 0 | U11: 0 | V11: 0 | W11: 0 | X11: 0 | Y11: 0 | Z11: 1 | AA11: 1 | AB11: 0 | AC11: 0 | AD11: 0 | AE11: 0 | AF11: 0 | AG11: 0 | AH11: 1 | AI11: 1 | AJ11: 1 | AK11: 1 | AL11: 1 | AM11: 1 | AN11: 1 | AO11: 1
A12: BT7 | B12: 1 | C12: 1 | D12: 1 | E12: 1 | F12: 1 | G12: 1 | H12: 1 | I12: 1 | J12: 1 | K12: 1 | L12: 1 | M12: 1 | N12: 1 | O12: 1 | P12: 1 | Q12: 1 | R12: 1 | S12: 1 | T12: 1 | U12: 1 | V12: 1 | W12: 1 | X12: 1 | Y12: 1 | Z12: 1 | AA12: 1 | AB12: 1 | AC12: 1 | AD12: 1 | AE12: 1 | AF12: 1 | AG12: 1 | AH12: 1 | AI12: 1 | AJ12: 1 | AK12: 1 | AL12: 1 | AM12: 1 | AN12: 1 | AO12: 1
A13: BT8 | B13: 0 | C13: 1 | D13: 1 | E13: 1 | F13: 0 | G13: 0 | H13: 0 | I13: 0 | J13: 0 | K13: 1 | L13: 1 | M13: 0 | N13: 0 | O13: 0 | P13: 0 | Q13: 0 | R13: 0 | S13: 0 | T13: 1 | U13: 1 | V13: 0 | W13: 0 | X13: 0 | Y13: 0 | Z13: 0 | AA13: 0 | AB13: 0 | AC13: 1 | AD13: 0 | AE13: 0 | AF13: 0 | AG13: 0 | AH13: 0 | AI13: 0 | AJ13: 0 | AK13: 0 | AL13: 0 | AM13: 0 | AN13: 0 | AO13: 0
A14: CM9 | B14: 1 | C14: 1 | D14: 1 | E14: 1 | F14: 1 | G14: 1 | H14: 0 | I14: 0 | J14: 1 | K14: 1 | L14: 1 | M14: 1 | N14: 1 | O14: 1 | P14: 1 | Q14: 0 | R14: 0 | S14: 0 | T14: 0 | U14: 0 | V14: 0 | W14: 0 | X14: 0 | Y14: 0 | Z14: 1 | AA14: 1 | AB14: 1 | AC14: 1 | AD14: 1 | AE14: 1 | AF14: 1 | AG14: 0 | AH14: 1 | AI14: 1 | AJ14: 1 | AK14: 1 | AL14: 1 | AM14: 0 | AN14: 0 | AO14: 0
A15: CF10 | B15: 1 | C15: 1 | D15: 1 | E15: 1 | F15: 1 | G15: 1 | H15: 1 | I15: 1 | J15: 1 | K15: 1 | L15: 1 | M15: 1 | N15: 1 | O15: 1 | P15: 1 | Q15: 1 | R15: 1 | S15: 1 | T15: 1 | U15: 1 | V15: 1 | W15: 1 | X15: 1 | Y15: 1 | Z15: 1 | AA15: 1 | AB15: 1 | AC15: 1 | AD15: 1 | AE15: 1 | AF15: 1 | AG15: 1 | AH15: 1 | AI15: 1 | AJ15: 1 | AK15: 1 | AL15: 1 | AM15: 1 | AN15: 1 | AO15: 1
A16: CT11 | B16: 1 | C16: 1 | D16: 1 | E16: 1 | F16: 1 | G16: 1 | H16: 0 | I16: 0 | J16: 0 | K16: 0 | L16: 0 | M16: 0 | N16: 0 | O16: 0 | P16: 0 | Q16: 0 | R16: 1 | S16: 1 | T16: 1 | U16: 1 | V16: 1 | W16: 1 | X16: 0 | Y16: 0 | Z16: 1 | AA16: 1 | AB16: 1 | AC16: 1 | AD16: 1 | AE16: 1 | AF16: 0 | AG16: 0 | AH16: 1 | AI16: 1 | AJ16: 1 | AK16: 1 | AL16: 1 | AM16: 1 | AN16: 1 | AO16: 1
A17: CR14 | B17: 1 | C17: 1 | D17: 1 | E17: 1 | F17: 1 | G17: 1 | H17: 1 | I17: 1 | J17: 1 | K17: 1 | L17: 1 | M17: 1 | N17: 1 | O17: 1 | P17: 1 | Q17: 1 | R17: 1 | S17: 1 | T17: 1 | U17: 1 | V17: 1 | W17: 1 | X17: 1 | Y17: 1 | Z17: 1 | AA17: 1 | AB17: 1 | AC17: 1 | AD17: 1 | AE17: 1 | AF17: 1 | AG17: 1 | AH17: 1 | AI17: 1 | AJ17: 1 | AK17: 1 | AL17: 1 | AM17: 1 | AN17: 1 | AO17: 1
A18: DS15 | B18: 1 | C18: 1 | D18: 1 | E18: 1 | F18: 1 | G18: 1 | H18: 1 | I18: 1 | J18: 1 | K18: 1 | L18: 1 | M18: 1 | N18: 1 | O18: 1 | P18: 1 | Q18: 1 | R18: 1 | S18: 1 | T18: 1 | U18: 1 | V18: 1 | W18: 1 | X18: 1 | Y18: 1 | Z18: 1 | AA18: 1 | AB18: 1 | AC18: 1 | AD18: 1 | AE18: 1 | AF18: 1 | AG18: 1 | AH18: 1 | AI18: 1 | AJ18: 1 | AK18: 1 | AL18: 1 | AM18: 1 | AN18: 1 | AO18: 1
A19: EA16 | B19: 1 | C19: 1 | D19: 1 | E19: 1 | F19: 1 | G19: 1 | H19: 0 | I19: 0 | J19: 1 | K19: 1 | L19: 1 | M19: 1 | N19: 1 | O19: 1 | P19: 1 | Q19: 1 | R19: 0 | S19: 0 | T19: 0 | U19: 0 | V19: 0 | W19: 0 | X19: 0 | Y19: 0 | Z19: 0 | AA19: 0 | AB19: 0 | AC19: 0 | AD19: 0 | AE19: 0 | AF19: 0 | AG19: 0 | AH19: 1 | AI19: 1 | AJ19: 1 | AK19: 1 | AL19: 1 | AM19: 1 | AN19: 1 | AO19: 1
A20: GL19 | B20: 1 | C20: 1 | D20: 1 | E20: 1 | F20: 1 | G20: 0 | H20: 0 | I20: 0 | J20: 1 | K20: 1 | L20: 1 | M20: 1 | N20: 1 | O20: 1 | P20: 1 | Q20: 1 | R20: 0 | S20: 0 | T20: 0 | U20: 0 | V20: 0 | W20: 0 | X20: 0 | Y20: 0 | Z20: 0 | AA20: 0 | AB20: 0 | AC20: 0 | AD20: 0 | AE20: 0 | AF20: 0 | AG20: 0 | AH20: 0 | AI20: 0 | AJ20: 0 | AK20: 0 | AL20: 0 | AM20: 0 | AN20: 0 | AO20: 0
... A60: DI63 | B60: 0 | C60: 0 | D60: 0 | E60: 0 | F60: 0 | G60: 0 | H60: 0 | I60: 0 | J60: 0 | K60: 1 | L60: 1 | M60: 1 | N60: 1 | O60: 1 | P60: 1 | Q60: 1 | R60: 0 | S60: 0 | T60: 0 | U60: 0 | V60: 0 | W60: 0 | X60: 0 | Y60: 0 | Z60: 0 | AA60: 1 | AB60: 1 | AC60: 1 | AD60: 1 | AE60: 1 | AF60: 1 | AG60: 1 | AH60: 0 | AI60: 1 | AJ60: 1 | AK60: 1 | AL60: 1 | AM60: 1 | AN60: 1 | AO60: 0
A61: SE64 | B61: 1 | C61: 1 | D61: 1 | E61: 1 | F61: 0 | G61: 0 | H61: 0 | I61: 0 | J61: 0 | K61: 1 | L61: 1 | M61: 1 | N61: 1 | O61: 1 | P61: 1 | Q61: 1 | R61: 1 | S61: 1 | T61: 1 | U61: 1 | V61: 0 | W61: 0 | X61: 0 | Y61: 0 | Z61: 0 | AA61: 0 | AB61: 0 | AC61: 0 | AD61: 1 | AE61: 1 | AF61: 1 | AG61: 1 | AH61: 1 | AI61: 1 | AJ61: 1 | AK61: 1 | AL61: 1 | AM61: 1 | AN61: 1
A62: YB65 | B62: 0 | C62: 0 | D62: 1 | E62: 1 | F62: 1 | G62: 0 | H62: 0 | I62: 0 | J62: 0 | K62: 0 | L62: 0 | M62: 0 | N62: 0 | O62: 0 | P62: 0 | Q62: 0 | R62: 0 | S62: 0 | T62: 1 | U62: 1 | V62: 1 | W62: 0 | X62: 0 | Y62: 0 | Z62: 0 | AA62: 0 | AB62: 1 | AC62: 1 | AD62: 1 | AE62: 0 | AF62: 0 | AG62: 0 | AH62: 0 | AI62: 0 | AJ62: 0 | AK62: 0 | AL62: 0 | AM62: 0 | AN62: 0 | AO62: 0
A63: FN66 | B63: 1 | C63: 1 | D63: 1 | E63: 1 | F63: 1 | G63: 1 | H63: 0 | I63: 0 | J63: 0 | K63: 0 | L63: 0 | M63: 0 | N63: 0 | O63: 0 | P63: 0 | Q63: 0 | R63: 1 | S63: 1 | T63: 1 | U63: 1 | V63: 1 | W63: 1 | X63: 0 | Y63: 0 | Z63: 0 | AA63: 0 | AB63: 0 | AC63: 0 | AD63: 0 | AE63: 0 | AF63: 0 | AG63: 0 | AH63: 0 | AI63: 0 | AJ63: 0 | AK63: 0 | AL63: 0 | AM63: 0 | AN63: 0 | AO63: 0
A64: PRC | B64: 1 | C64: 1 | D64: 1 | E64: 1 | F64: 1 | G64: 1 | H64: 1 | I64: 1 | J64: 1 | K64: 1 | L64: 1 | M64: 1 | N64: 1 | O64: 1 | P64: 1 | Q64: 1 | R64: 1 | S64: 1 | T64: 1 | U64: 1 | V64: 1 | W64: 1 | X64: 1 | Y64: 1 | Z64: 1 | AA64: 1 | AB64: 1 | AC64: 1 | AD64: 1 | AE64: 1 | AF64: 1 | AG64: 1 | AH64: 1 | AI64: 1 | AJ64: 1 | AK64: 1 | AL64: 1 | AM64: 1 | AN64: 1 | AO64: 1
A65: ING1 | B65: 1 | C65: 1 | D65: 1 | E65: 1 | F65: 1 | G65: 1 | H65: 1 | I65: 1 | J65: 1 | K65: 1 | L65: 1 | M65: 1 | N65: 1 | O65: 1 | P65: 1 | Q65: 1 | R65: 1 | S65: 1 | T65: 1 | U65: 1 | V65: 1 | W65: 1 | X65: 1 | Y65: 1 | Z65: 1 | AA65: 1 | AB65: 1 | AC65: 1 | AD65: 1 | AE65: 1 | AF65: 1 | AG65: 1 | AH65: 1 | AI65: 1 | AJ65: 1 | AK65: 1 | AL65: 1 | AM65: 1 | AN65: 1 | AO65: 1
A66: ING2 | B66: 1 | C66: 1 | D66: 1 | E66: 1 | F66: 1 | G66: 1 | H66: 1 | I66: 1 | J66: 1 | K66: 1 | L66: 1 | M66: 1 | N66: 1 | O66: 1 | P66: 1 | Q66: 1 | R66: 1 | S66: 1 | T66: 1 | U66: 1 | V66: 1 | W66: 1 | X66: 1 | Y66: 1 | Z66: 1 | AA66: 1 | AB66: 1 | AC66: 1 | AD66: 1 | AE66: 1 | AF66: 1 | AG66: 1 | AH66: 1 | AI66: 1 | AJ66: 1 | AK66: 1 | AL66: 1 | AM66: 1 | AN66: 1 | AO66: 1
A67: ING3 | B67: 1 | C67: 1 | D67: 1 | E67: 1 | F67: 1 | G67: 1 | H67: 1 | I67: 1 | J67: 1 | K67: 1 | L67: 1 | M67: 1 | N67: 1 | O67: 1 | P67: 1 | Q67: 1 | R67: 1 | S67: 1 | T67: 1 | U67: 1 | V67: 1 | W67: 1 | X67: 1 | Y67: 1 | Z67: 1 | AA67: 1 | AB67: 1 | AC67: 1 | AD67: 1 | AE67: 1 | AF67: 1 | AG67: 1 | AH67: 1 | AI67: 1 | AJ67: 1 | AK67: 1 | AL67: 1 | AM67: 1 | AN67: 1 | AO67: 1
A68: ING4 | B68: 1 | C68: 1 | D68: 1 | E68: 1 | F68: 1 | G68: 1 | H68: 1 | I68: 1 | J68: 1 | K68: 1 | L68: 1 | M68: 1 | N68: 1 | O68: 1 | P68: 1 | Q68: 1 | R68: 1 | S68: 1 | T68: 1 | U68: 1 | V68: 1 | W68: 1 | X68: 1 | Y68: 1 | Z68: 1 | AA68: 1 | AB68: 1 | AC68: 1 | AD68: 1 | AE68: 1 | AF68: 1 | AG68: 1 | AH68: 1 | AI68: 1 | AJ68: 1 | AK68: 1 | AL68: 1 | AM68: 1 | AN68: 1 | AO68: 1
A69: ING5 | B69: 1 | C69: 1 | D69: 1 | E69: 1 | F69: 1 | G69: 1 | H69: 1 | I69: 1 | J69: 1 | K69: 1 | L69: 1 | M69: 1 | N69: 1 | O69: 1 | P69: 1 | Q69: 1 | R69: 1 | S69: 1 | T69: 1 | U69: 1 | V69: 1 | W69: 1 | X69: 1 | Y69: 1 | Z69: 1 | AA69: 1 | AB69: 1 | AC69: 1 | AD69: 1 | AE69: 1 | AF69: 1 | AG69: 1 | AH69: 1 | AI69: 1 | AJ69: 1 | AK69: 1 | AL69: 1 | AM69: 1 | AN69: 1 | AO69: 1
A70: ING6 | B70: 1 | C70: 1 | D70: 1 | E70: 1 | F70: 1 | G70: 1 | H70: 1 | I70: 1 | J70: 1 | K70: 1 | L70: 1 | M70: 1 | N70: 1 | O70: 1 | P70: 1 | Q70: 1 | R70: 1 | S70: 1 | T70: 1 | U70: 1 | V70: 1 | W70: 1 | X70: 1 | Y70: 1 | Z70: 1 | AA70: 1 | AB70: 1 | AC70: 1 | AD70: 1 | AE70: 1 | AF70: 1 | AG70: 1 | AH70: 1 | AI70: 1 | AJ70: 1 | AK70: 1 | AL70: 1 | AM70: 1 | AN70: 1 | AO70: 1
A71: ING7 | B71: 1 | C71: 1 | D71: 1 | E71: 1 | F71: 1 | G71: 1 | H71: 1 | I71: 1 | J71: 1 | K71: 1 | L71: 1 | M71: 1 | N71: 1 | O71: 1 | P71: 1 | Q71: 1 | R71: 1 | S71: 1 | T71: 1 | U71: 1 | V71: 1 | W71: 1 | X71: 1 | Y71: 1 | Z71: 1 | AA71: 1 | AB71: 1 | AC71: 1 | AD71: 1 | AE71: 1 | AF71: 1 | AG71: 1 | AH71: 1 | AI71: 1 | AJ71: 1 | AK71: 1 | AL71: 1 | AM71: 1 | AN71: 1 | AO71: 1
A72: ING8 | B72: 1 | C72: 1 | D72: 1 | E72: 1 | F72: 1 | G72: 1 | H72: 1 | I72: 1 | J72: 1 | K72: 1 | L72: 1 | M72: 1 | N72: 1 | O72: 1 | P72: 1 | Q72: 1 | R72: 1 | S72: 1 | T72: 1 | U72: 1 | V72: 1 | W72: 1 | X72: 1 | Y72: 1 | Z72: 1 | AA72: 1 | AB72: 1 | AC72: 1 | AD72: 1 | AE72: 1 | AF72: 1 | AG72: 1 | AH72: 1 | AI72: 1 | AJ72: 1 | AK72: 1 | AL72: 1 | AM72: 1 | AN72: 1 | AO72: 1
A73: ING9 | B73: 1 | C73: 1 | D73: 1 | E73: 1 | F73: 1 | G73: 1 | H73: 1 | I73: 1 | J73: 1 | K73: 1 | L73: 1 | M73: 1 | N73: 1 | O73: 1 | P73: 1 | Q73: 1 | R73: 1 | S73: 1 | T73: 1 | U73: 1 | V73: 1 | W73: 1 | X73: 1 | Y73: 1 | Z73: 1 | AA73: 1 | AB73: 1 | AC73: 1 | AD73: 1 | AE73: 1 | AF73: 1 | AG73: 1 | AH73: 1 | AI73: 1 | AJ73: 1 | AK73: 1 | AL73: 1 | AM73: 1 | AN73: 1 | AO73: 1
... A82: ING18 | B82: 1 | C82: 1 | D82: 1 | E82: 1 | F82: 1 | G82: 1 | H82: 1 | I82: 1 | J82: 1 | K82: 1 | L82: 1 | M82: 1 | N82: 1 | O82: 1 | P82: 1 | Q82: 1 | R82: 1 | S82: 1 | T82: 1 | U82: 1 | V82: 1 | W82: 1 | X82: 1 | Y82: 1 | Z82: 1 | AA82: 1 | AB82: 1 | AC82: 1 | AD82: 1 | AE82: 1 | AF82: 1 | AG82: 1 | AH82: 1 | AI82: 1 | AJ82: 1 | AK82: 1 | AL82: 1 | AM82: 1 | AN82: 1 | AO82: 1

Sheet Subjects
A2: Subject | B2: Number of lessons | C2: Duration (Hours) | D2: Total Hours | E2: Professor | F2: Course
A3: {=UNIQUE(Names!C3:C1000)} -> C.Ciudadana 1A | B3: 1 | C3: 2 | D3: =B3*C3 -> 2 | E3: AC1 | F3: 1A
A4: C.Ciudadana 1B | B4: 1 | C4: 2 | D4: =B4*C4 -> 2 | E4: AC1 | F4: 1B
A5: C.Ciudadana 1C | B5: 1 | C5: 2 | D5: =B5*C5 -> 2 | E5: AC1 | F5: 1C
A6: C.Ciudadana 2A | B6: 1 | C6: 2 | D6: =B6*C6 -> 2 | E6: SS45 | F6: 2A
A7: C.Ciudadana 2B | B7: 1 | C7: 2 | D7: =B7*C7 -> 2 | E7: AC1 | F7: 2B
A8: C.Ciudadana 2C | B8: 1 | C8: 2 | D8: =B8*C8 -> 2 | E8: SS45 | F8: 2C
A9: C.Ciudadana 3A | B9: 1 | C9: 2 | D9: =B9*C9 -> 2 | E9: TA50 | F9: 3A
A10: C.Ciudadana 3B | B10: 1 | C10: 2 | D10: =B10*C10 -> 2 | E10: TA50 | F10: 3B
A11: C.Ciudadana 3C | B11: 1 | C11: 2 | D11: =B11*C11 -> 2 | E11: ZM52 | F11: 3C
A12: Matemática 1A | B12: 2 | C12: 2 | D12: =B12*C12 -> 4 | E12: ZC53 | F12: 1A
A13: Matemática 1B | B13: 2 | C13: 2 | D13: =B13*C13 -> 4 | E13: ZC53 | F13: 1B
A14: Matemática 1C | B14: 2 | C14: 2 | D14: =B14*C14 -> 4 | E14: ZC53 | F14: 1C
A15: Matemática 2A | B15: 2 | C15: 2 | D15: =B15*C15 -> 4 | E15: ZC53 | F15: 2A
... A228: Taller FHC 6N | B228: 1 | C228: 2 | D228: =B228*C228 -> 2 | E228: PRC | F228: 6N

Sheet _hours_per_course
A1: Course | B1: Total hours
A2: {=UNIQUE(Names!A3:A999)} -> 1A | B2: {=MAKEARRAY(Names!A2, 1, LAMBDA(r, c, SUMIFS(Subjects!$D$3:$D999, Subjects!$F$3:$F999, OFFSET($A2, r-1, 0))))} -> 34
A3: 1B | B3: 34
A4: 1C | B4: 34
A5: 2A | B5: 34
A6: 2B | B6: 34
A7: 2C | B7: 34
A8: 3A | B8: 34
A9: 3B | B9: 34
A10: 3C | B10: 34
A11: 4E | B11: 33
A12: 4S | B12: 31
A13: 4N | B13: 31
A14: 5E | B14: 34
... A19: 6N | B19: 33

Sheet _hours_per_professor
A1: Professor | B1: Total hours
A2: {=UNIQUE(Names!B3:B999)} -> AC1 | B2: {=MAKEARRAY(Names!B2, 1, LAMBDA(r, c, SUMIFS(Subjects!$D$3:$D999, Subjects!$E$3:$E999, OFFSET($A2, r-1, 0))))} -> 8
A3: AA2 | B3: 0
A4: AH4 | B4: 10
A5: BL6 | B5: 2
A6: BT7 | B6: 8
A7: BT8 | B7: 6
A8: CM9 | B8: 23
A9: CF10 | B9: 12
A10: CT11 | B10: 21
A11: CR14 | B11: 5
A12: DS15 | B12: 0
A13: EA16 | B13: 18
A14: GL19 | B14: 3
... A76: ING18 | B76: 4

Sheet _hours_per_course_per_professor
B1: {=TRANSPOSE(UNIQUE(Names!B3:B1000))} -> AC1 | C1: AA2 | D1: AH4 | E1: BL6 | F1: BT7 | G1: BT8 | H1: CM9 | I1: CF10 | J1: CT11 | K1: CR14 | L1: DS15 | M1: EA16 | N1: GL19 | O1: GD20 | P1: GI21 | Q1: GA22 | R1: GA23 | S1: GK24 | T1: HN25 | U1: ME26 | V1: MF28 | W1: NL29 | X1: OM30 | Y1: PV32 | Z1: PV33 | AA1: PM34 | AB1: RD35 | AC1: RM36 | AD1: RM37 | AE1: RB38 | AF1: RA39 | AG1: SM41 | AH1: SC42 | AI1: SL43 | AJ1: SP44 | AK1: SS45 | AL1: SM46 | AM1: SV47 | AN1: TR49 | AO1: TA50 | AP1: TE51 | AQ1: ZM52 | AR1: ZC53 | AS1: RL54 | AT1: VF55 | AU1: FM56 | AV1: MG57 | AW1: DV58 | AX1: BM59 | AY1: DF60 | AZ1: MR61 | BA1: OS62 | BB1: DI63 | BC1: SE64 | BD1: YB65 | BE1: FN66 | BF1: PRC | BG1: ING1 | BH1: ING2 | BI1: ING3 | BJ1: ING4 | BK1: ING5 | BL1: ING6 | BM1: ING7 | BN1: ING8 | BO1: ING9 | BP1: ING10 | BQ1: ING11 | BR1: ING12 | BS1: ING13 | BT1: ING14 | BU1: ING15 | BV1: ING16 | BW1: ING17 | BX1: ING18
A2: {=UNIQUE(Names!A3:A1000)} -> 1A | B2: {=MAKEARRAY(Names!A2, Names!B2, LAMBDA(r, c, SUMIFS(Subjects!$D$3:$D1000, Subjects!$E$3:$E1000, OFFSET(B$1, 0, c-1), Subjects!$F$3:$F1000, OFFSET($A2, r-1, 0))))} -> 2 | C2: 0 | D2: 0 | E2: 0 | F2: 2 | G2: 0 | H2: 4 | I2: 0 | J2: 0 | K2: 0 | L2: 0 | M2: 2 | N2: 0 | O2: 0 | P2: 0 | Q2: 0 | R2: 0 | S2: 0 | T2: 4 | U2: 0 | V2: 0 | W2: 0 | X2: 0 | Y2: 0 | Z2: 0 | AA2: 0 | AB2: 0 | AC2: 0 | AD2: 4 | AE2: 0 | AF2: 0 | AG2: 0 | AH2: 0 | AI2: 0 | AJ2: 0 | AK2: 0 | AL2: 0 | AM2: 0 | AN2: 1 | AO2: 0 | AP2: 0 | AQ2: 0 | AR2: 4 | AS2: 2 | AT2: 0 | AU2: 0 | AV2: 0 | AW2: 0 | AX2: 0 | AY2: 0 | AZ2: 0 | BA2: 0 | BB2: 0 | BC2: 0 | BD2: 0 | BE2: 0 | BF2: 0 | BG2: 9 | BH2: 0 | BI2: 0 | BJ2: 0 | BK2: 0 | BL2: 0 | BM2: 0 | BN2: 0 | BO2: 0 | BP2: 0 | BQ2: 0 | BR2: 0 | BS2: 0 | BT2: 0 | BU2: 0 | BV2: 0 | BW2: 0 | BX2: 0
A3: 1B | B3: 2 | C3: 0 | D3: 0 | E3: 0 | F3: 0 | G3: 2 | H3: 4 | I3: 0 | J3: 0 | K3: 0 | L3: 0 | M3: 2 | N3: 0 | O3: 0 | P3: 0 | Q3: 0 | R3: 0 | S3: 0 | T3: 4 | U3: 0 | V3: 0 | W3: 2 | X3: 0 | Y3: 0 | Z3: 0 | AA3: 0 | AB3: 0 | AC3: 0 | AD3: 4 | AE3: 0 | AF3: 0 | AG3: 0 | AH3: 0 | AI3: 0 | AJ3: 0 | AK3: 0 | AL3: 0 | AM3: 0 | AN3: 1 | AO3: 0 | AP3: 0 | AQ3: 0 | AR3: 4 | AS3: 0 | AT3: 0 | AU3: 0 | AV3: 0 | AW3: 0 | AX3: 0 | AY3: 0 | AZ3: 0 | BA3: 0 | BB3: 0 | BC3: 0 | BD3: 0 | BE3: 0 | BF3: 0 | BG3: 0 | BH3: 9 | BI3: 0 | BJ3: 0 | BK3: 0 | BL3: 0 | BM3: 0 | BN3: 0 | BO3: 0 | BP3: 0 | BQ3: 0 | BR3: 0 | BS3: 0 | BT3: 0 | BU3: 0 | BV3: 0 | BW3: 0 | BX3: 0
A4: 1C | B4: 2 | C4: 0 | D4: 0 | E4: 0 | F4: 2 | G4: 0 | H4: 4 | I4: 0 | J4: 0 | K4: 0 | L4: 0 | M4: 2 | N4: 0 | O4: 0 | P4: 0 | Q4: 0 | R4: 0 | S4: 0 | T4: 4 | U4: 0 | V4: 0 | W4: 0 | X4: 0 | Y4: 0 | Z4: 0 | AA4: 0 | AB4: 0 | AC4: 0 | AD4: 4 | AE4: 0 | AF4: 0 | AG4: 0 | AH4: 0 | AI4: 0 | AJ4: 0 | AK4: 0 | AL4: 0 | AM4: 0 | AN4: 1 | AO4: 0 | AP4: 0 | AQ4: 0 | AR4: 4 | AS4: 2 | AT4: 0 | AU4: 0 | AV4: 0 | AW4: 0 | AX4: 0 | AY4: 0 | AZ4: 0 | BA4: 0 | BB4: 0 | BC4: 0 | BD4: 0 | BE4: 0 | BF4: 0 | BG4: 0 | BH4: 0 | BI4: 9 | BJ4: 0 | BK4: 0 | BL4: 0 | BM4: 0 | BN4: 0 | BO4: 0 | BP4: 0 | BQ4: 0 | BR4: 0 | BS4: 0 | BT4: 0 | BU4: 0 | BV4: 0 | BW4: 0 | BX4: 0
A5: 2A | B5: 0 | C5: 0 | D5: 0 | E5: 0 | F5: 2 | G5: 0 | H5: 0 | I5: 0 | J5: 0 | K5: 0 | L5: 0 | M5: 2 | N5: 0 | O5: 0 | P5: 0 | Q5: 0 | R5: 0 | S5: 0 | T5: 0 | U5: 2 | V5: 0 | W5: 0 | X5: 0 | Y5: 0 | Z5: 0 | AA5: 2 | AB5: 0 | AC5: 0 | AD5: 4 | AE5: 0 | AF5: 0 | AG5: 0 | AH5: 2 | AI5: 0 | AJ5: 0 | AK5: 2 | AL5: 2 | AM5: 0 | AN5: 0 | AO5: 0 | AP5: 0 | AQ5: 2 | AR5: 4 | AS5: 2 | AT5: 0 | AU5: 0 | AV5: 0 | AW5: 0 | AX5: 0 | AY5: 0 | AZ5: 0 | BA5: 0 | BB5: 0 | BC5: 0 | BD5: 0 | BE5: 0 | BF5: 0 | BG5: 0 | BH5: 0 | BI5: 0 | BJ5: 8 | BK5: 0 | BL5: 0 | BM5: 0 | BN5: 0 | BO5: 0 | BP5: 0 | BQ5: 0 | BR5: 0 | BS5: 0 | BT5: 0 | BU5: 0 | BV5: 0 | BW5: 0 | BX5: 0
A6: 2B | B6: 2 | C6: 0 | D6: 0 | E6: 0 | F6: 2 | G6: 0 | H6: 0 | I6: 0 | J6: 0 | K6: 0 | L6: 0 | M6: 2 | N6: 0 | O6: 0 | P6: 0 | Q6: 0 | R6: 0 | S6: 0 | T6: 0 | U6: 2 | V6: 2 | W6: 2 | X6: 0 | Y6: 0 | Z6: 0 | AA6: 2 | AB6: 0 | AC6: 0 | AD6: 4 | AE6: 0 | AF6: 0 | AG6: 0 | AH6: 2 | AI6: 0 | AJ6: 0 | AK6: 0 | AL6: 0 | AM6: 0 | AN6: 0 | AO6: 0 | AP6: 0 | AQ6: 2 | AR6: 4 | AS6: 0 | AT6: 0 | AU6: 0 | AV6: 0 | AW6: 0 | AX6: 0 | AY6: 0 | AZ6: 0 | BA6: 0 | BB6: 0 | BC6: 0 | BD6: 0 | BE6: 0 | BF6: 0 | BG6: 0 | BH6: 0 | BI6: 0 | BJ6: 0 | BK6: 8 | BL6: 0 | BM6: 0 | BN6: 0 | BO6: 0 | BP6: 0 | BQ6: 0 | BR6: 0 | BS6: 0 | BT6: 0 | BU6: 0 | BV6: 0 | BW6: 0 | BX6: 0
A7: 2C | B7: 0 | C7: 0 | D7: 0 | E7: 0 | F7: 0 | G7: 2 | H7: 0 | I7: 0 | J7: 0 | K7: 0 | L7: 0 | M7: 2 | N7: 0 | O7: 0 | P7: 0 | Q7: 0 | R7: 0 | S7: 0 | T7: 2 | U7: 0 | V7: 0 | W7: 0 | X7: 0 | Y7: 0 | Z7: 0 | AA7: 4 | AB7: 0 | AC7: 0 | AD7: 4 | AE7: 0 | AF7: 0 | AG7: 0 | AH7: 2 | AI7: 0 | AJ7: 2 | AK7: 2 | AL7: 0 | AM7: 0 | AN7: 0 | AO7: 0 | AP7: 0 | AQ7: 2 | AR7: 4 | AS7: 0 | AT7: 0 | AU7: 0 | AV7: 0 | AW7: 0 | AX7: 0 | AY7: 0 | AZ7: 0 | BA7: 0 | BB7: 0 | BC7: 0 | BD7: 0 | BE7: 0 | BF7: 0 | BG7: 0 | BH7: 0 | BI7: 0 | BJ7: 0 | BK7: 0 | BL7: 8 | BM7: 0 | BN7: 0 | BO7: 0 | BP7: 0 | BQ7: 0 | BR7: 0 | BS7: 0 | BT7: 0 | BU7: 0 | BV7: 0 | BW7: 0 | BX7: 0
A8: 3A | B8: 0 | C8: 0 | D8: 2 | E8: 0 | F8: 0 | G8: 0 | H8: 0 | I8: 4 | J8: 0 | K8: 0 | L8: 0 | M8: 0 | N8: 1 | O8: 0 | P8: 0 | Q8: 0 | R8: 0 | S8: 0 | T8: 2 | U8: 0 | V8: 0 | W8: 0 | X8: 0 | Y8: 0 | Z8: 0 | AA8: 4 | AB8: 0 | AC8: 0 | AD8: 0 | AE8: 4 | AF8: 0 | AG8: 0 | AH8: 2 | AI8: 0 | AJ8: 0 | AK8: 0 | AL8: 0 | AM8: 0 | AN8: 0 | AO8: 2 | AP8: 0 | AQ8: 2 | AR8: 0 | AS8: 0 | AT8: 1 | AU8: 0 | AV8: 0 | AW8: 0 | AX8: 0 | AY8: 2 | AZ8: 0 | BA8: 0 | BB8: 0 | BC8: 0 | BD8: 0 | BE8: 0 | BF8: 0 | BG8: 0 | BH8: 0 | BI8: 0 | BJ8: 0 | BK8: 0 | BL8: 0 | BM8: 8 | BN8: 0 | BO8: 0 | BP8: 0 | BQ8: 0 | BR8: 0 | BS8: 0 | BT8: 0 | BU8: 0 | BV8: 0 | BW8: 0 | BX8: 0
A9: 3B | B9: 0 | C9: 0 | D9: 2 | E9: 0 | F9: 0 | G9: 0 | H9: 0 | I9: 4 | J9: 0 | K9: 0 | L9: 0 | M9: 0 | N9: 1 | O9: 0 | P9: 0 | Q9: 0 | R9: 0 | S9: 0 | T9: 0 | U9: 0 | V9: 0 | W9: 0 | X9: 0 | Y9: 0 | Z9: 0 | AA9: 4 | AB9: 0 | AC9: 0 | AD9: 0 | AE9: 4 | AF9: 0 | AG9: 0 | AH9: 2 | AI9: 0 | AJ9: 0 | AK9: 0 | AL9: 2 | AM9: 0 | AN9: 0 | AO9: 2 | AP9: 0 | AQ9: 2 | AR9: 0 | AS9: 0 | AT9: 1 | AU9: 0 | AV9: 0 | AW9: 0 | AX9: 0 | AY9: 2 | AZ9: 0 | BA9: 0 | BB9: 0 | BC9: 0 | BD9: 0 | BE9: 0 | BF9: 0 | BG9: 0 | BH9: 0 | BI9: 0 | BJ9: 0 | BK9: 0 | BL9: 0 | BM9: 0 | BN9: 8 | BO9: 0 | BP9: 0 | BQ9: 0 | BR9: 0 | BS9: 0 | BT9: 0 | BU9: 0 | BV9: 0 | BW9: 0 | BX9: 0
A10: 3C | B10: 0 | C10: 0 | D10: 2 | E10: 0 | F10: 0 | G10: 0 | H10: 0 | I10: 4 | J10: 0 | K10: 0 | L10: 0 | M10: 0 | N10: 1 | O10: 0 | P10: 0 | Q10: 0 | R10: 0 | S10: 0 | T10: 0 | U10: 0 | V10: 0 | W10: 0 | X10: 0 | Y10: 0 | Z10: 0 | AA10: 4 | AB10: 0 | AC10: 0 | AD10: 0 | AE10: 4 | AF10: 0 | AG10: 0 | AH10: 2 | AI10: 0 | AJ10: 0 | AK10: 0 | AL10: 2 | AM10: 0 | AN10: 0 | AO10: 0 | AP10: 0 | AQ10: 4 | AR10: 0 | AS10: 0 | AT10: 1 | AU10: 0 | AV10: 0 | AW10: 0 | AX10: 0 | AY10: 2 | AZ10: 0 | BA10: 0 | BB10: 0 | BC10: 0 | BD10: 0 | BE10: 0 | BF10: 0 | BG10: 0 | BH10: 0 | BI10: 0 | BJ10: 0 | BK10: 0 | BL10: 0 | BM10: 0 | BN10: 0 | BO10: 8 | BP10: 0 | BQ10: 0 | BR10: 0 | BS10: 0 | BT10: 0 | BU10: 0 | BV10: 0 | BW10: 0 | BX10: 0
A11: 4E | B11: 0 | C11: 0 | D11: 0 | E11: 0 | F11: 0 | G11: 2 | H11: 2 | I11: 0 | J11: 3 | K11: 0 | L11: 0 | M11: 2 | N11: 0 | O11: 0 | P11: 0 | Q11: 0 | R11: 0 | S11: 0 | T11: 3 | U11: 0 | V11: 0 | W11: 0 | X11: 0 | Y11: 0 | Z11: 0 | AA11: 0 | AB11: 0 | AC11: 0 | AD11: 0 | AE11: 0 | AF11: 3 | AG11: 0 | AH11: 0 | AI11: 0 | AJ11: 0 | AK11: 0 | AL11: 0 | AM11: 3 | AN11: 0 | AO11: 2 | AP11: 3 | AQ11: 0 | AR11: 0 | AS11: 0 | AT11: 0 | AU11: 0 | AV11: 0 | AW11: 0 | AX11: 1 | AY11: 0 | AZ11: 4 | BA11: 0 | BB11: 0 | BC11: 0 | BD11: 0 | BE11: 0 | BF11: 0 | BG11: 0 | BH11: 0 | BI11: 0 | BJ11: 0 | BK11: 0 | BL11: 0 | BM11: 0 | BN11: 0 | BO11: 0 | BP11: 5 | BQ11: 0 | BR11: 0 | BS11: 0 | BT11: 0 | BU11: 0 | BV11: 0 | BW11: 0 | BX11: 0
A12: 4S | B12: 0 | C12: 0 | D12: 2 | E12: 0 | F12: 0 | G12: 0 | H12: 2 | I12: 0 | J12: 3 | K12: 0 | L12: 0 | M12: 2 | N12: 0 | O12: 0 | P12: 0 | Q12: 0 | R12: 0 | S12: 0 | T12: 3 | U12: 0 | V12: 0 | W12: 0 | X12: 0 | Y12: 0 | Z12: 0 | AA12: 0 | AB12: 0 | AC12: 0 | AD12: 0 | AE12: 0 | AF12: 3 | AG12: 0 | AH12: 0 | AI12: 0 | AJ12: 0 | AK12: 0 | AL12: 0 | AM12: 3 | AN12: 0 | AO12: 2 | AP12: 3 | AQ12: 0 | AR12: 0 | AS12: 0 | AT12: 0 | AU12: 0 | AV12: 2 | AW12: 0 | AX12: 1 | AY12: 0 | AZ12: 0 | BA12: 0 | BB12: 0 | BC12: 0 | BD12: 0 | BE12: 0 | BF12: 0 | BG12: 0 | BH12: 0 | BI12: 0 | BJ12: 0 | BK12: 0 | BL12: 0 | BM12: 0 | BN12: 0 | BO12: 0 | BP12: 0 | BQ12: 5 | BR12: 0 | BS12: 0 | BT12: 0 | BU12: 0 | BV12: 0 | BW12: 0 | BX12: 0
A13: 4N | B13: 0 | C13: 0 | D13: 2 | E13: 0 | F13: 0 | G13: 0 | H13: 2 | I13: 0 | J13: 3 | K13: 0 | L13: 0 | M13: 2 | N13: 0 | O13: 0 | P13: 0 | Q13: 3 | R13: 0 | S13: 0 | T13: 3 | U13: 0 | V13: 0 | W13: 0 | X13: 0 | Y13: 0 | Z13: 0 | AA13: 0 | AB13: 0 | AC13: 0 | AD13: 0 | AE13: 0 | AF13: 2 | AG13: 0 | AH13: 0 | AI13: 0 | AJ13: 0 | AK13: 0 | AL13: 0 | AM13: 3 | AN13: 0 | AO13: 2 | AP13: 0 | AQ13: 0 | AR13: 3 | AS13: 0 | AT13: 0 | AU13: 0 | AV13: 0 | AW13: 0 | AX13: 1 | AY13: 0 | AZ13: 0 | BA13: 0 | BB13: 0 | BC13: 0 | BD13: 0 | BE13: 0 | BF13: 0 | BG13: 0 | BH13: 0 | BI13: 0 | BJ13: 0 | BK13: 0 | BL13: 0 | BM13: 0 | BN13: 0 | BO13: 0 | BP13: 0 | BQ13: 0 | BR13: 5 | BS13: 0 | BT13: 0 | BU13: 0 | BV13: 0 | BW13: 0 | BX13: 0
A14: 5E | B14: 0 | C14: 0 | D14: 0 | E14: 0 | F14: 0 | G14: 0 | H14: 0 | I14: 0 | J14: 2 | K14: 3 | L14: 0 | M14: 0 | N14: 0 | O14: 0 | P14: 0 | Q14: 3 | R14: 0 | S14: 0 | T14: 0 | U14: 0 | V14: 0 | W14: 0 | X14: 0 | Y14: 0 | Z14: 0 | AA14: 0 | AB14: 0 | AC14: 0 | AD14: 0 | AE14: 2 | AF14: 2 | AG14: 0 | AH14: 0 | AI14: 0 | AJ14: 0 | AK14: 0 | AL14: 2 | AM14: 0 | AN14: 0 | AO14: 2 | AP14: 0 | AQ14: 0 | AR14: 0 | AS14: 0 | AT14: 0 | AU14: 0 | AV14: 0 | AW14: 0 | AX14: 0 | AY14: 4 | AZ14: 8 | BA14: 0 | BB14: 0 | BC14: 0 | BD14: 0 | BE14: 0 | BF14: 2 | BG14: 0 | BH14: 0 | BI14: 0 | BJ14: 0 | BK14: 0 | BL14: 0 | BM14: 0 | BN14: 0 | BO14: 0 | BP14: 0 | BQ14: 0 | BR14: 0 | BS14: 4 | BT14: 0 | BU14: 0 | BV14: 0 | BW14: 0 | BX14: 0
... A19: 6N | B19: 0 | C19: 0 | D19: 0 | E19: 0 | F19: 0 | G19: 0 | H19: 5 | I19: 0 | J19: 2 | K19: 0 | L19: 0 | M19: 0 | N19: 0 | O19: 0 | P19: 2 | Q19: 3 | R19: 0 | S19: 0 | T19: 0 | U19: 0 | V19: 0 | W19: 0 | X19: 0 | Y19: 0 | Z19: 3 | AA19: 0 | AB19: 0 | AC19: 0 | AD19: 0 | AE19: 0 | AF19: 3 | AG19: 0 | AH19: 0 | AI19: 0 | AJ19: 0 | AK19: 2 | AL19: 2 | AM19: 0 | AN19: 0 | AO19: 0 | AP19: 4 | AQ19: 0 | AR19: 0 | AS19: 0 | AT19: 0 | AU19: 0 | AV19: 0 | AW19: 1 | AX19: 0 | AY19: 0 | AZ19: 0 | BA19: 0 | BB19: 0 | BC19: 0 | BD19: 0 | BE19: 0 | BF19: 2 | BG19: 0 | BH19: 0 | BI19: 0 | BJ19: 0 | BK19: 0 | BL19: 0 | BM19: 0 | BN19: 0 | BO19: 0 | BP19: 0 | BQ19: 0 | BR19: 0 | BS19: 0 | BT19: 0 | BU19: 0 | BV19: 0 | BW19: 0 | BX19: 4
